<?xml version="1.0" ?>
<!-- =================================================================================== -->
<!-- |    This document was autogenerated by xacro from rrbot.xacro                    | -->
<!-- |    EDITING THIS FILE BY HAND IS NOT RECOMMENDED                                 | -->
<!-- =================================================================================== -->
<!-- Revolute-Revolute Manipulator -->
<robot name="rrbot">
  <!-- damping coefficient -->
  <!-- ros_control plugin -->
  <gazebo>
    <plugin filename="libgazebo_ros_control.so" name="gazebo_ros_control">
      <robotNamespace>/rrbot</robotNamespace>
      <robotSimType>gazebo_ros_control/DefaultRobotHWSim</robotSimType>
    </plugin>
  </gazebo>
  <!-- Middle Link -->
  <gazebo reference="mid_link">
    <mu>0.2</mu>
    <mu2>0.2</mu2>
    <material>Gazebo/Green</material>
  </gazebo>
  <link name="plate_link">
    <visual>
      <origin rpy="0 0 0" xyz="0 0 0"/>
      <geometry>
        <cylinder length="0.01" radius="0.2"/>
      </geometry>
      <material name="yellow"/>
    </visual>
    <collision>
      <origin rpy="0 0 0" xyz=" 0 0 0 "/>
      <geometry>
        <cylinder length="0.01" radius="0.2"/>
      </geometry>
    </collision>
    <inertial>
      <origin rpy="0 0 0" xyz="0 0 0.05"/>
      <mass value="0.1"/>
      <inertia ixx="1.0" ixy="0.0" ixz="0.0" iyy="1.0" iyz="0.0" izz="1.0"/>
    </inertial>
  </link>
  <!-- Joint between Plate and Arm Link -->
  <joint name="joint_plate_arm" type="fixed">
    <parent link="arm_link"/>
    <child link="plate"/>
    <origin rpy="0 0 0" xyz="0 0.02 0.09000000000000001"/>
    <axis xyz="0 0 0"/>
    <dynamics damping="0.2"/>
    <limit effort="100.0" lower="-3.14" upper="3.14" velocity="0.5"/>
  </joint>
  <joint name="fixed" type="fixed">
    <parent link="base_link"/>
    <child link="arm_link"/>
    <origin rpy="0 0 0" xyz="-0.14 0 0.1"/>
  </joint>
  <!-- Arm Link -->
  <link name="arm_link">
    <visual>
      <origin rpy="0 0 0" xyz="0 0 0.05"/>
      <geometry>
        <box size="0.02 0.02 0.1"/>
      </geometry>
      <material name="red"/>
    </visual>
    <collision>
      <origin rpy="0 0 0" xyz="0 0 0.05"/>
      <geometry>
        <box size="0.02 0.02 0.1"/>
      </geometry>
    </collision>
    <inertial>
      <origin rpy="0 0 0" xyz="0 0 0.05"/>
      <mass value="0.1"/>
      <inertia ixx="1.0" ixy="0.0" ixz="0.0" iyy="1.0" iyz="0.0" izz="1.0"/>
    </inertial>
  </link>
  <!-- Joint between Base Link and Middle Link -->
  <joint name="joint_base_mid" type="prismatic">
    <parent link="arm_link"/>
    <child link="mid_link"/>
    <origin rpy="0 0 0" xyz="0 0.02 0.09000000000000001"/>
    <axis xyz="0 0 1"/>
    <dynamics damping="0.2"/>
    <limit effort="100.0" lower="-3.14" upper="3.14" velocity="0.5"/>
  </joint>
  <!-- Middle Link -->
  <link name="mid_link">
    <visual>
      <origin rpy="0 0 0" xyz="0 0 0.115"/>
      <geometry>
        <box size="0.02 0.02 0.25"/>
      </geometry>
      <material name="green"/>
    </visual>
    <collision>
      <origin rpy="0 0 0" xyz="0 0 0.115"/>
      <geometry>
        <box size="0.02 0.02 0.25"/>
      </geometry>
    </collision>
    <inertial>
      <origin rpy="0 0 0" xyz="0 0 0.115"/>
      <mass value="0.1"/>
      <inertia ixx="1.0" ixy="0.0" ixz="0.0" iyy="1.0" iyz="0.0" izz="1.0"/>
    </inertial>
  </link>
  <transmission name="transmission1">
    <type>transmission_interface/SimpleTransmission</type>
    <joint name="joint_base_mid">
      <hardwareInterface>hardware_interface/EffortJointInterface</hardwareInterface>
    </joint>
    <actuator name="motor1">
      <mechanicalReduction>1</mechanicalReduction>
    </actuator>
  </transmission>
</robot>

